Workbook

Sheet Dashboard
B1: Distribuidora Aurora Ltda — Dashboard Financeiro
B2: 1º Semestre de 2026 (Janeiro a Junho) · Fonte: aba Recebimentos
B5: TOTAL RECEBIDO | F5: Nº DE RECEBIMENTOS | J5: TICKET MÉDIO | N5: MELHOR MÊS | R5: MAIOR CLIENTE
B6: =Dashboard!$AC$81 -> 4218199 | F6: =Dashboard!$AC$82 -> 222 | J6: =Dashboard!$AC$83 -> 19000.896 | N6: =Dashboard!$AD$84 -> Abril | R6: =Dashboard!$AD$85 -> Supermercado Familia
B8: jan a jun / 2026 | F8: pagamentos no semestre | J8: ="por recebimento ("&Dashboard!$AC$82&" pagtos)" -> por recebimento (222 pagtos) | N8: =Dashboard!$AE$84 -> 864938.31 | R8: =Dashboard!$AE$85 -> 1149147.3
AB66: Tabelas de apoio dos gráficos (fora da área de impressão)
AB67: Mês | AC67: Valor | AD67: Mês (extenso) | AF67: Região/UF | AG67: Valor | AI67: Categoria | AJ67: Valor | AL67: Cliente | AM67: Valor
AB68: Jan | AC68: =SUMPRODUCT((MONTH(Recebimentos!$A$5:$A$226)=1)*Recebimentos!$C$5:$C$226) -> 631363.98 | AD68: Janeiro | AF68: Norte/PA | AG68: =SUMIF(Recebimentos!$E$5:$E$226,"Norte/PA",Recebimentos!$C$5:$C$226) -> 1149147.3 | AI68: Hortifruti | AJ68: =SUMIF(Recebimentos!$F$5:$F$226,"Hortifruti",Recebimentos!$C$5:$C$226) -> 1643579.3 | AL68: Comercial Amazonas | AM68: =SUMIF(Recebimentos!$B$5:$B$226,"Comercial Amazonas",Recebimentos!$C$5:$C$226) -> 6168.09
AB69: Fev | AC69: =SUMPRODUCT((MONTH(Recebimentos!$A$5:$A$226)=2)*Recebimentos!$C$5:$C$226) -> 661449.66 | AD69: Fevereiro | AF69: Sudeste/SP | AG69: =SUMIF(Recebimentos!$E$5:$E$226,"Sudeste/SP",Recebimentos!$C$5:$C$226) -> 948100.78 | AI69: Bebidas | AJ69: =SUMIF(Recebimentos!$F$5:$F$226,"Bebidas",Recebimentos!$C$5:$C$226) -> 1273092.1 | AL69: Bar e Restaurante Estrela do Sul | AM69: =SUMIF(Recebimentos!$B$5:$B$226,"Bar e Restaurante Estrela do Sul",Recebimentos!$C$5:$C$226) -> 7040
AB70: Mar | AC70: =SUMPRODUCT((MONTH(Recebimentos!$A$5:$A$226)=3)*Recebimentos!$C$5:$C$226) -> 719121.93 | AD70: Março | AF70: Nordeste/PE | AG70: =SUMIF(Recebimentos!$E$5:$E$226,"Nordeste/PE",Recebimentos!$C$5:$C$226) -> 885660.97 | AI70: Mercearia | AJ70: =SUMIF(Recebimentos!$F$5:$F$226,"Mercearia",Recebimentos!$C$5:$C$226) -> 895164.33 | AL70: Padaria e Confeitaria Trigo de Ouro | AM70: =SUMIF(Recebimentos!$B$5:$B$226,"Padaria e Confeitaria Trigo de Ouro",Recebimentos!$C$5:$C$226) -> 8330
AB71: Abr | AC71: =SUMPRODUCT((MONTH(Recebimentos!$A$5:$A$226)=4)*Recebimentos!$C$5:$C$226) -> 864938.31 | AD71: Abril | AF71: Centro-Oeste/GO | AG71: =SUMIF(Recebimentos!$E$5:$E$226,"Centro-Oeste/GO",Recebimentos!$C$5:$C$226) -> 494431.98 | AI71: Congelados | AJ71: =SUMIF(Recebimentos!$F$5:$F$226,"Congelados",Recebimentos!$C$5:$C$226) -> 299786.48 | AL71: Mercearia Sao Joaquim | AM71: =SUMIF(Recebimentos!$B$5:$B$226,"Mercearia Sao Joaquim",Recebimentos!$C$5:$C$226) -> 20567.47
AB72: Mai | AC72: =SUMPRODUCT((MONTH(Recebimentos!$A$5:$A$226)=5)*Recebimentos!$C$5:$C$226) -> 599898.29 | AD72: Maio | AF72: Sul/RS | AG72: =SUMIF(Recebimentos!$E$5:$E$226,"Sul/RS",Recebimentos!$C$5:$C$226) -> 387431.18 | AI72: Não identificado | AJ72: =SUMIF(Recebimentos!$F$5:$F$226,"",Recebimentos!$C$5:$C$226) -> 58209.18 | AL72: Emporio Vila Nova Ltda | AM72: =SUMIF(Recebimentos!$B$5:$B$226,"Emporio Vila Nova Ltda",Recebimentos!$C$5:$C$226) -> 22271.71
AB73: Jun | AC73: =SUMPRODUCT((MONTH(Recebimentos!$A$5:$A$226)=6)*Recebimentos!$C$5:$C$226) -> 741426.85 | AD73: Junho | AF73: Nordeste/CE | AG73: =SUMIF(Recebimentos!$E$5:$E$226,"Nordeste/CE",Recebimentos!$C$5:$C$226) -> 156261.92 | AI73: Higiene e Limpeza | AJ73: =SUMIF(Recebimentos!$F$5:$F$226,"Higiene e Limpeza",Recebimentos!$C$5:$C$226) -> 48367.59 | AL73: Rede Farmacias Popular | AM73: =SUMIF(Recebimentos!$B$5:$B$226,"Rede Farmacias Popular",Recebimentos!$C$5:$C$226) -> 42199.5
AF74: Centro-Oeste/MT | AG74: =SUMIF(Recebimentos!$E$5:$E$226,"Centro-Oeste/MT",Recebimentos!$C$5:$C$226) -> 90588.11 | AL74: Frigorifico Vale Verde | AM74: =SUMIF(Recebimentos!$B$5:$B$226,"Frigorifico Vale Verde",Recebimentos!$C$5:$C$226) -> 90588.11
AF75: Não identificado | AG75: =SUMIF(Recebimentos!$E$5:$E$226,"",Recebimentos!$C$5:$C$226) -> 58209.18 | AL75: Mercadao Central | AM75: =SUMIF(Recebimentos!$B$5:$B$226,"Mercadao Central",Recebimentos!$C$5:$C$226) -> 156261.92
AF76: Sul/PR | AG76: =SUMIF(Recebimentos!$E$5:$E$226,"Sul/PR",Recebimentos!$C$5:$C$226) -> 42199.5 | AL76: Rede Supermercados Mais | AM76: =SUMIF(Recebimentos!$B$5:$B$226,"Rede Supermercados Mais",Recebimentos!$C$5:$C$226) -> 209198.37
AF77: Norte/AM | AG77: =SUMIF(Recebimentos!$E$5:$E$226,"Norte/AM",Recebimentos!$C$5:$C$226) -> 6168.09 | AL77: Distribuidora Bebidas Lopes | AM77: =SUMIF(Recebimentos!$B$5:$B$226,"Distribuidora Bebidas Lopes",Recebimentos!$C$5:$C$226) -> 387431.18
AL78: Hortifruti Natural | AM78: =SUMIF(Recebimentos!$B$5:$B$226,"Hortifruti Natural",Recebimentos!$C$5:$C$226) -> 494431.98
AL79: Atacado Uniao Comercial | AM79: =SUMIF(Recebimentos!$B$5:$B$226,"Atacado Uniao Comercial",Recebimentos!$C$5:$C$226) -> 738902.41
AB80: Resumo (cálculo auxiliar dos cartões) | AL80: Adega Ponto do Vinho | AM80: =SUMIF(Recebimentos!$B$5:$B$226,"Adega Ponto do Vinho",Recebimentos!$C$5:$C$226) -> 885660.97
AB81: Total Recebido | AC81: =SUM(Recebimentos!$C$5:$C$226) -> 4218199 | AL81: Supermercado Familia | AM81: =SUMIF(Recebimentos!$B$5:$B$226,"Supermercado Familia",Recebimentos!$C$5:$C$226) -> 1149147.3
AB82: Nº de Recebimentos | AC82: =COUNT(Recebimentos!$C$5:$C$226) -> 222
AB83: Ticket Médio | AC83: =$AC$81/$AC$82 -> 19000.896
AB84: Melhor Mês (nome / valor) | AD84: =INDEX($AD$68:$AD$73,MATCH(MAX($AC$68:$AC$73),$AC$68:$AC$73,0)) -> Abril | AE84: =MAX($AC$68:$AC$73) -> 864938.31
AB85: Maior Cliente (nome / valor) | AD85: =INDEX($AL$68:$AL$81,MATCH(MAX($AM$68:$AM$81),$AM$68:$AM$81,0)) -> Supermercado Familia | AE85: =MAX($AM$68:$AM$81) -> 1149147.3

Sheet Recebimentos
A1: Distribuidora Aurora Ltda - Controle de Recebimentos
A2: 1o semestre de 2026 (janeiro a junho)
A4: Data | B4: Cliente | C4: Valor (R$) | D4: Forma de Pagamento | E4: Regiao/UF | F4: Categoria
A5: 46023 | B5: Atacado Uniao Comercial | C5: 19870 | D5: Boleto | E5: Sudeste/SP | F5: Mercearia
A6: 46027 | B6: Supermercado Familia | C6: 14870 | D6: Boleto | E6: Norte/PA | F6: Hortifruti
A7: 46028 | B7: Hortifruti Natural | C7: 32588.48 | D7: Pix | E7: Centro-Oeste/GO | F7: Hortifruti
A8: 46030 | B8: Distribuidora Bebidas Lopes | C8: 21750 | D8: Pix | E8: Sul/RS | F8: Bebidas
A9: 46033 | B9: Adega Ponto do Vinho | C9: 51323.96 | D9: Boleto | E9: Nordeste/PE | F9: Bebidas
A10: 46034 | B10: Hortifruti Natural | C10: 5350 | D10: Deposito | E10: Centro-Oeste/GO | F10: Hortifruti
A11: 46035 | B11: Supermercado Familia | C11: 12800 | D11: Pix | E11: Norte/PA | F11: Hortifruti
A12: 46035 | B12: Rede Farmacias Popular | C12: 8179.8 | D12: Boleto | E12: Sul/PR | F12: Higiene e Limpeza
A13: 46035 | B13: Supermercado Familia | C13: 17910 | D13: Boleto | E13: Norte/PA | F13: Hortifruti
A14: 46035 | B14: Atacado Uniao Comercial | C14: 18200 | D14: Boleto | E14: Sudeste/SP | F14: Mercearia
A15: 46035 | B15: Rede Supermercados Mais | C15: 41510 | D15: Pix | E15: Sudeste/SP | F15: Congelados
A16: 46036 | B16: Mercadao Central | C16: 6510 | D16: Pix | E16: Nordeste/CE | F16: Mercearia
... A43: 46058 | B43: Distribuidora Bebidas Lopes | C43: 14980 | D43: Boleto | E43: Sul/RS | F43: Bebidas
A44: 46059 | B44: Padaria e Confeitaria Trigo de Ouro | C44: 8330 | D44: Deposito
A45: 46062 | B45: Frigorifico Vale Verde | C45: 6280 | D45: Pix | E45: Centro-Oeste/MT | F45: Congelados
A46: 46064 | B46: Bar e Restaurante Estrela do Sul | C46: 7040 | D46: Pix
A47: 46065 | B47: Atacado Uniao Comercial | C47: 22930 | D47: Pix | E47: Sudeste/SP | F47: Mercearia
A48: 46066 | B48: Supermercado Familia | C48: 14580 | D48: Boleto | E48: Norte/PA | F48: Hortifruti
A49: 46066 | B49: Rede Supermercados Mais | C49: 13198.52 | D49: Pix | E49: Sudeste/SP | F49: Congelados
A50: 46066 | B50: Distribuidora Bebidas Lopes | C50: 29770 | D50: Pix | E50: Sul/RS | F50: Bebidas
A51: 46068 | B51: Frigorifico Vale Verde | C51: 4740 | D51: Pix | E51: Centro-Oeste/MT | F51: Congelados
A52: 46068 | B52: Supermercado Familia | C52: 9226.7 | D52: Transferencia | E52: Norte/PA | F52: Hortifruti
A53: 46069 | B53: Supermercado Familia | C53: 20420 | D53: Boleto | E53: Norte/PA | F53: Hortifruti
A54: 46069 | B54: Hortifruti Natural | C54: 9270 | D54: Deposito | E54: Centro-Oeste/GO | F54: Hortifruti
A55: 46070 | B55: Supermercado Familia | C55: 12990 | D55: Boleto | E55: Norte/PA | F55: Hortifruti
A56: 46070 | B56: Atacado Uniao Comercial | C56: 65960 | D56: TED | E56: Sudeste/SP | F56: Mercearia
A57: 46070 | B57: Adega Ponto do Vinho | C57: 9730 | D57: Boleto | E57: Nordeste/PE | F57: Bebidas
A58: 46070 | B58: Hortifruti Natural | C58: 13759.65 | D58: Boleto | E58: Centro-Oeste/GO | F58: Hortifruti
... A88: 46097 | B88: Rede Farmacias Popular | C88: 8650 | D88: Deposito | E88: Sul/PR | F88: Higiene e Limpeza
A89: 46098 | B89: Emporio Vila Nova Ltda | C89: 22271.71 | D89: Boleto
A90: 46098 | B90: Frigorifico Vale Verde | C90: 7260 | D90: Boleto | E90: Centro-Oeste/MT | F90: Congelados
A91: 46101 | B91: Adega Ponto do Vinho | C91: 30356.99 | D91: Pix | E91: Nordeste/PE | F91: Bebidas
A92: 46104 | B92: Hortifruti Natural | C92: 31290 | D92: Deposito | E92: Centro-Oeste/GO | F92: Hortifruti
A93: 46104 | B93: Frigorifico Vale Verde | C93: 5330 | D93: Boleto | E93: Centro-Oeste/MT | F93: Congelados
A94: 46104 | B94: Comercial Amazonas | C94: 380 | D94: Pix | E94: Norte/AM | F94: Higiene e Limpeza
A95: 46105 | B95: Adega Ponto do Vinho | C95: 18260 | D95: Pix | E95: Nordeste/PE | F95: Bebidas
A96: 46105 | B96: Adega Ponto do Vinho | C96: 7336.41 | D96: Pix | E96: Nordeste/PE | F96: Bebidas
...

Sheet Cadastro de Clientes
A1: Cadastro de Clientes
A2: Base cadastral da Aurora
A4: Cliente | B4: Regiao/UF | C4: Categoria
A5: Adega Ponto do Vinho | B5: Nordeste/PE | C5: Bebidas
A6: Atacado Uniao Comercial | B6: Sudeste/SP | C6: Mercearia
A7: Comercial Amazonas | B7: Norte/AM | C7: Higiene e Limpeza
A8: Distribuidora Bebidas Lopes | B8: Sul/RS | C8: Bebidas
A9: Frigorifico Vale Verde | B9: Centro-Oeste/MT | C9: Congelados
A10: Hortifruti Natural | B10: Centro-Oeste/GO | C10: Hortifruti
A11: Mercadao Central | B11: Nordeste/CE | C11: Mercearia
A12: Rede Farmacias Popular | B12: Sul/PR | C12: Higiene e Limpeza
A13: Rede Supermercados Mais | B13: Sudeste/SP | C13: Congelados
A14: Supermercado Familia | B14: Norte/PA | C14: Hortifruti
